<?xml version="1.0" encoding="UTF-8"?>
<!-- Generated by org.testng.reporters.JUnitReportReporter -->
<testsuite hostname="bcd0746442bd.ant.amazon.com" failures="2" tests="2" name="com.w2a.rough.AssertionTests" time="0.025" errors="0" timestamp="2023-03-30T14:59:24 IST" skipped="0">
  <testcase classname="com.w2a.rough.AssertionTests" name="softAssertion" time="0.022">
    <failure message="The following asserts failed:
	expected [google] but found [yahoo]" type="java.lang.AssertionError">
      <![CDATA[java.lang.AssertionError: The following asserts failed:
expected [google] but found [yahoo]
at org.testng.asserts.SoftAssert.assertAll(SoftAssert.java:46)
at org.testng.asserts.SoftAssert.assertAll(SoftAssert.java:30)
at com.w2a.rough.AssertionTests.softAssertion(AssertionTests.java:26)
at java.base/jdk.internal.reflect.NativeMethodAccessorImpl.invoke0(Native Method)
at java.base/jdk.internal.reflect.NativeMethodAccessorImpl.invoke(NativeMethodAccessorImpl.java:77)
at java.base/jdk.internal.reflect.DelegatingMethodAccessorImpl.invoke(DelegatingMethodAccessorImpl.java:43)
at java.base/java.lang.reflect.Method.invoke(Method.java:568)
at org.testng.internal.invokers.MethodInvocationHelper.invokeMethod(MethodInvocationHelper.java:139)
at org.testng.internal.invokers.TestInvoker.invokeMethod(TestInvoker.java:677)
at org.testng.internal.invokers.TestInvoker.invokeTestMethod(TestInvoker.java:221)
at org.testng.internal.invokers.MethodRunner.runInSequence(MethodRunner.java:50)
at org.testng.internal.invokers.TestInvoker$MethodInvocationAgent.invoke(TestInvoker.java:969)
at org.testng.internal.invokers.TestInvoker.invokeTestMethods(TestInvoker.java:194)
at org.testng.internal.invokers.TestMethodWorker.invokeTestMethods(TestMethodWorker.java:148)
at org.testng.internal.invokers.TestMethodWorker.run(TestMethodWorker.java:128)
at java.base/java.util.ArrayList.forEach(ArrayList.java:1511)
at org.testng.TestRunner.privateRun(TestRunner.java:829)
at org.testng.TestRunner.run(TestRunner.java:602)
at org.testng.SuiteRunner.runTest(SuiteRunner.java:437)
at org.testng.SuiteRunner.runSequentially(SuiteRunner.java:431)
at org.testng.SuiteRunner.privateRun(SuiteRunner.java:391)
at org.testng.SuiteRunner.run(SuiteRunner.java:330)
at org.testng.SuiteRunnerWorker.runSuite(SuiteRunnerWorker.java:52)
at org.testng.SuiteRunnerWorker.run(SuiteRunnerWorker.java:95)
at org.testng.TestNG.runSuitesSequentially(TestNG.java:1256)
at org.testng.TestNG.runSuitesLocally(TestNG.java:1176)
at org.testng.TestNG.runSuites(TestNG.java:1099)
at org.testng.TestNG.run(TestNG.java:1067)
at org.testng.remote.AbstractRemoteTestNG.run(AbstractRemoteTestNG.java:115)
at org.testng.remote.RemoteTestNG.initAndRun(RemoteTestNG.java:251)
at org.testng.remote.RemoteTestNG.main(RemoteTestNG.java:77)
]]>
    </failure>
  </testcase> <!-- softAssertion -->
  <system-out>
    <![CDATA[<a href="/Users/sinhapoo/git/DDF/_flag_ae.png" target="_blank">Screenshot link ----  </a>
<br>
<a href="/Users/sinhapoo/git/DDF/_flag_ae.png" target="_blank"><img height=200 width=200 src="/Users/sinhapoo/git/DDF/_flag_ae.png"> </a>]]>
  </system-out>
  <testcase classname="com.w2a.rough.AssertionTests" name="validateTitle" time="0.003">
    <failure message="some message I can put expected [true] but found [false]" type="java.lang.AssertionError">
      <![CDATA[java.lang.AssertionError: some message I can put expected [true] but found [false]
at org.testng.Assert.fail(Assert.java:110)
at org.testng.Assert.failNotEquals(Assert.java:1413)
at org.testng.Assert.assertEqualsImpl(Assert.java:149)
at org.testng.Assert.assertEquals(Assert.java:131)
at org.testng.Assert.assertEquals(Assert.java:976)
at com.w2a.rough.AssertionTests.validateTitle(AssertionTests.java:16)
at java.base/jdk.internal.reflect.NativeMethodAccessorImpl.invoke0(Native Method)
at java.base/jdk.internal.reflect.NativeMethodAccessorImpl.invoke(NativeMethodAccessorImpl.java:77)
at java.base/jdk.internal.reflect.DelegatingMethodAccessorImpl.invoke(DelegatingMethodAccessorImpl.java:43)
at java.base/java.lang.reflect.Method.invoke(Method.java:568)
at org.testng.internal.invokers.MethodInvocationHelper.invokeMethod(MethodInvocationHelper.java:139)
at org.testng.internal.invokers.TestInvoker.invokeMethod(TestInvoker.java:677)
at org.testng.internal.invokers.TestInvoker.invokeTestMethod(TestInvoker.java:221)
at org.testng.internal.invokers.MethodRunner.runInSequence(MethodRunner.java:50)
at org.testng.internal.invokers.TestInvoker$MethodInvocationAgent.invoke(TestInvoker.java:969)
at org.testng.internal.invokers.TestInvoker.invokeTestMethods(TestInvoker.java:194)
at org.testng.internal.invokers.TestMethodWorker.invokeTestMethods(TestMethodWorker.java:148)
at org.testng.internal.invokers.TestMethodWorker.run(TestMethodWorker.java:128)
at java.base/java.util.ArrayList.forEach(ArrayList.java:1511)
at org.testng.TestRunner.privateRun(TestRunner.java:829)
at org.testng.TestRunner.run(TestRunner.java:602)
at org.testng.SuiteRunner.runTest(SuiteRunner.java:437)
at org.testng.SuiteRunner.runSequentially(SuiteRunner.java:431)
at org.testng.SuiteRunner.privateRun(SuiteRunner.java:391)
at org.testng.SuiteRunner.run(SuiteRunner.java:330)
at org.testng.SuiteRunnerWorker.runSuite(SuiteRunnerWorker.java:52)
at org.testng.SuiteRunnerWorker.run(SuiteRunnerWorker.java:95)
at org.testng.TestNG.runSuitesSequentially(TestNG.java:1256)
at org.testng.TestNG.runSuitesLocally(TestNG.java:1176)
at org.testng.TestNG.runSuites(TestNG.java:1099)
at org.testng.TestNG.run(TestNG.java:1067)
at org.testng.remote.AbstractRemoteTestNG.run(AbstractRemoteTestNG.java:115)
at org.testng.remote.RemoteTestNG.initAndRun(RemoteTestNG.java:251)
at org.testng.remote.RemoteTestNG.main(RemoteTestNG.java:77)
]]>
    </failure>
  </testcase> <!-- validateTitle -->
  <system-out>
    <![CDATA[<a href="/Users/sinhapoo/git/DDF/_flag_ae.png" target="_blank">Screenshot link ----  </a>
<br>
<a href="/Users/sinhapoo/git/DDF/_flag_ae.png" target="_blank"><img height=200 width=200 src="/Users/sinhapoo/git/DDF/_flag_ae.png"> </a>]]>
  </system-out>
</testsuite> <!-- com.w2a.rough.AssertionTests -->
